package pkgExceptionHandling;
import java.util.Random;

public class RandomDivisionEx {
	/**
	 * This method generates two random numbers and performs division on them.
	 * In case of exception, it is handled by try-catch block.
	 */
	public static int randomDiv() {
		Random rndNum = new Random();  // creating object of Random class to generate random numbers
		int num1 = rndNum.nextInt(1);  // generates random number between 0 (inclusive) and specified value (exclusive)
		int num2 = rndNum.nextInt(10);
		int result = 0;
		try {
			System.out.println("The first number is: " + num1);
			System.out.println("The second number is: " + num2);
			result = num1/num2;
		}
		catch(ArithmeticException ae) {
			System.out.println("Exception: " + ae);
		}
		return result;
	}
	public static void main(String [] args) {
		System.out.println(randomDiv());
	}
}
